2017-10-24 22:10:22.956888: W tensorflow/core/platform/cpu_feature_guard.cc:45] The TensorFlow library wasn't compiled to use SSE4.1 instructions, but these are available on your machine and could speed up CPU computations.
2017-10-24 22:10:22.957371: W tensorflow/core/platform/cpu_feature_guard.cc:45] The TensorFlow library wasn't compiled to use SSE4.2 instructions, but these are available on your machine and could speed up CPU computations.
2017-10-24 22:10:22.957388: W tensorflow/core/platform/cpu_feature_guard.cc:45] The TensorFlow library wasn't compiled to use AVX instructions, but these are available on your machine and could speed up CPU computations.
2017-10-24 22:10:23.193103: W tensorflow/core/framework/op_kernel.cc:1192] Not found: Key Variable_6/Adam not found in checkpoint
2017-10-24 22:10:23.198512: W tensorflow/core/framework/op_kernel.cc:1192] Not found: Key Variable_6/Adam_1 not found in checkpoint
2017-10-24 22:10:23.206593: W tensorflow/core/framework/op_kernel.cc:1192] Not found: Key Variable_7/Adam not found in checkpoint
2017-10-24 22:10:23.210858: W tensorflow/core/framework/op_kernel.cc:1192] Not found: Key Variable_8/Adam not found in checkpoint
2017-10-24 22:10:23.215084: W tensorflow/core/framework/op_kernel.cc:1192] Not found: Key Variable_8/Adam_1 not found in checkpoint
2017-10-24 22:10:23.215235: W tensorflow/core/framework/op_kernel.cc:1192] Not found: Key Variable_7/Adam_1 not found in checkpoint
Traceback (most recent call last):
  File "/home/taylor/.local/lib/python3.5/site-packages/tensorflow/python/client/session.py", line 1327, in _do_call
    return fn(*args)
  File "/home/taylor/.local/lib/python3.5/site-packages/tensorflow/python/client/session.py", line 1306, in _run_fn
    status, run_metadata)
  File "/usr/lib/python3.5/contextlib.py", line 66, in __exit__
    next(self.gen)
  File "/home/taylor/.local/lib/python3.5/site-packages/tensorflow/python/framework/errors_impl.py", line 466, in raise_exception_on_not_ok_status
    pywrap_tensorflow.TF_GetCode(status))
tensorflow.python.framework.errors_impl.NotFoundError: Key Variable_6/Adam not found in checkpoint
	 [[Node: save/RestoreV2_22 = RestoreV2[dtypes=[DT_FLOAT], _device="/job:localhost/replica:0/task:0/cpu:0"](_arg_save/Const_0_0, save/RestoreV2_22/tensor_names, save/RestoreV2_22/shape_and_slices)]]

During handling of the above exception, another exception occurred:

Traceback (most recent call last):
  File "../../run.py", line 7, in <module>
    model.run()
  File "/home/taylor/ba/model.py", line 221, in run
    saver.restore(sess, self.checkpoint_path)
  File "/home/taylor/.local/lib/python3.5/site-packages/tensorflow/python/training/saver.py", line 1560, in restore
    {self.saver_def.filename_tensor_name: save_path})
  File "/home/taylor/.local/lib/python3.5/site-packages/tensorflow/python/client/session.py", line 895, in run
    run_metadata_ptr)
  File "/home/taylor/.local/lib/python3.5/site-packages/tensorflow/python/client/session.py", line 1124, in _run
    feed_dict_tensor, options, run_metadata)
  File "/home/taylor/.local/lib/python3.5/site-packages/tensorflow/python/client/session.py", line 1321, in _do_run
    options, run_metadata)
  File "/home/taylor/.local/lib/python3.5/site-packages/tensorflow/python/client/session.py", line 1340, in _do_call
    raise type(e)(node_def, op, message)
tensorflow.python.framework.errors_impl.NotFoundError: Key Variable_6/Adam not found in checkpoint
	 [[Node: save/RestoreV2_22 = RestoreV2[dtypes=[DT_FLOAT], _device="/job:localhost/replica:0/task:0/cpu:0"](_arg_save/Const_0_0, save/RestoreV2_22/tensor_names, save/RestoreV2_22/shape_and_slices)]]

Caused by op 'save/RestoreV2_22', defined at:
  File "../../run.py", line 7, in <module>
    model.run()
  File "/home/taylor/ba/model.py", line 218, in run
    saver = tf.train.Saver()
  File "/home/taylor/.local/lib/python3.5/site-packages/tensorflow/python/training/saver.py", line 1140, in __init__
    self.build()
  File "/home/taylor/.local/lib/python3.5/site-packages/tensorflow/python/training/saver.py", line 1172, in build
    filename=self._filename)
  File "/home/taylor/.local/lib/python3.5/site-packages/tensorflow/python/training/saver.py", line 688, in build
    restore_sequentially, reshape)
  File "/home/taylor/.local/lib/python3.5/site-packages/tensorflow/python/training/saver.py", line 407, in _AddRestoreOps
    tensors = self.restore_op(filename_tensor, saveable, preferred_shard)
  File "/home/taylor/.local/lib/python3.5/site-packages/tensorflow/python/training/saver.py", line 247, in restore_op
    [spec.tensor.dtype])[0])
  File "/home/taylor/.local/lib/python3.5/site-packages/tensorflow/python/ops/gen_io_ops.py", line 663, in restore_v2
    dtypes=dtypes, name=name)
  File "/home/taylor/.local/lib/python3.5/site-packages/tensorflow/python/framework/op_def_library.py", line 767, in apply_op
    op_def=op_def)
  File "/home/taylor/.local/lib/python3.5/site-packages/tensorflow/python/framework/ops.py", line 2630, in create_op
    original_op=self._default_original_op, op_def=op_def)
  File "/home/taylor/.local/lib/python3.5/site-packages/tensorflow/python/framework/ops.py", line 1204, in __init__
    self._traceback = self._graph._extract_stack()  # pylint: disable=protected-access

NotFoundError (see above for traceback): Key Variable_6/Adam not found in checkpoint
	 [[Node: save/RestoreV2_22 = RestoreV2[dtypes=[DT_FLOAT], _device="/job:localhost/replica:0/task:0/cpu:0"](_arg_save/Const_0_0, save/RestoreV2_22/tensor_names, save/RestoreV2_22/shape_and_slices)]]

